{"data_type": "CVE", "data_format": "MITRE", "data_version": "4.0", "CVE_data_meta": {"ID": "CVE-2018-12565", "ASSIGNER": "cve@mitre.org"}, "affects": {"vendor": {"vendor_data": [{"vendor_name": "debian", "product": {"product_data": [{"product_name": "debian_linux", "version": {"version_data": [{"version_value": "9.0", "version_affected": "="}]}}]}}]}}, "problemtype": {"problemtype_data": [{"description": [{"lang": "en", "value": "CWE-20"}]}]}, "references": {"reference_data": [{"url": "https://git.linaro.org/lava/lava.git/commit/?id=583666c84ea2f12797a3eb71392bcb05782f5b14", "name": "https://git.linaro.org/lava/lava.git/commit/?id=583666c84ea2f12797a3eb71392bcb05782f5b14", "refsource": "CONFIRM", "tags": ["Patch", "Third Party Advisory"]}, {"url": "https://www.debian.org/security/2018/dsa-4234", "name": "DSA-4234", "refsource": "DEBIAN", "tags": ["Third Party Advisory"]}]}, "description": {"description_data": [{"lang": "en", "value": "An issue was discovered in Linaro LAVA before 2018.5.post1. Because of use of yaml.load() instead of yaml.safe_load() when parsing user data, remote code execution can occur."}]}}
